CRITICAL - 2021-05-02 22:05:40 --> Unable to connect to the database.
#0 C:\xampp\htdocs\ejb\vendor\codeigniter4\framework\system\Database\BaseConnection.php(646): CodeIgniter\Database\BaseConnection->initialize()
#1 C:\xampp\htdocs\ejb\vendor\codeigniter4\framework\system\Database\BaseBuilder.php(1860): CodeIgniter\Database\BaseConnection->query('SELECT *\nFROM `...', Array, false)
#2 C:\xampp\htdocs\ejb\vendor\codeigniter4\framework\system\Model.php(506): CodeIgniter\Database\BaseBuilder->get()
#3 C:\xampp\htdocs\ejb\app\ThirdParty\myth-auth\src\Authentication\LocalAuthenticator.php(156): CodeIgniter\Model->first()
#4 C:\xampp\htdocs\ejb\app\ThirdParty\myth-auth\src\Authentication\LocalAuthenticator.php(20): Myth\Auth\Authentication\LocalAuthenticator->validate(Array, true)
#5 C:\xampp\htdocs\ejb\app\ThirdParty\myth-auth\src\Controllers\AuthController.php(90): Myth\Auth\Authentication\LocalAuthenticator->attempt(Array, false)
#6 C:\xampp\htdocs\ejb\vendor\codeigniter4\framework\system\CodeIgniter.php(918): Myth\Auth\Controllers\AuthController->attemptLogin()
#7 C:\xampp\htdocs\ejb\vendor\codeigniter4\framework\system\CodeIgniter.php(404): CodeIgniter\CodeIgniter->runController(Object(Myth\Auth\Controllers\AuthController))
#8 C:\xampp\htdocs\ejb\vendor\codeigniter4\framework\system\CodeIgniter.php(312): CodeIgniter\CodeIgniter->handleRequest(NULL, Object(Config\Cache), false)
#9 C:\xampp\htdocs\ejb\public\index.php(45): CodeIgniter\CodeIgniter->run()
#10 C:\xampp\htdocs\ejb\vendor\codeigniter4\framework\system\Commands\Server\rewrite.php(34): require_once('C:\\xampp\\htdocs...')
#11 {main}
CRITICAL - 2021-05-02 22:05:40 --> Uncaught ErrorException: print_r(): Property access is not allowed yet in C:\xampp\htdocs\ejb\app\Views\errors\html\error_exception.php:100
Stack trace:
#0 [internal function]: CodeIgniter\Debug\Exceptions->errorHandler(2, 'print_r(): Prop...', 'C:\\xampp\\htdocs...', 100, Array)
#1 C:\xampp\htdocs\ejb\app\Views\errors\html\error_exception.php(100): print_r(Object(Myth\Auth\Controllers\AuthController), true)
#2 C:\xampp\htdocs\ejb\vendor\codeigniter4\framework\system\Debug\Exceptions.php(308): include('C:\\xampp\\htdocs...')
#3 C:\xampp\htdocs\ejb\vendor\codeigniter4\framework\system\Debug\Exceptions.php(174): CodeIgniter\Debug\Exceptions->render(Object(CodeIgniter\Database\Exceptions\DatabaseException), 500)
#4 [internal function]: CodeIgniter\Debug\Exceptions->exceptionHandler(Object(CodeIgniter\Database\Exceptions\DatabaseException))
#5 {main}
  thrown
#0 [internal function]: CodeIgniter\Debug\Exceptions->shutdownHandler()
#1 {main}
CRITICAL - 2021-05-02 22:06:22 --> Unable to connect to the database.
#0 C:\xampp\htdocs\ejb\vendor\codeigniter4\framework\system\Database\BaseConnection.php(646): CodeIgniter\Database\BaseConnection->initialize()
#1 C:\xampp\htdocs\ejb\vendor\codeigniter4\framework\system\Database\BaseBuilder.php(1860): CodeIgniter\Database\BaseConnection->query('SELECT *\nFROM `...', Array, false)
#2 C:\xampp\htdocs\ejb\vendor\codeigniter4\framework\system\Model.php(506): CodeIgniter\Database\BaseBuilder->get()
#3 C:\xampp\htdocs\ejb\app\ThirdParty\myth-auth\src\Authentication\LocalAuthenticator.php(156): CodeIgniter\Model->first()
#4 C:\xampp\htdocs\ejb\app\ThirdParty\myth-auth\src\Authentication\LocalAuthenticator.php(20): Myth\Auth\Authentication\LocalAuthenticator->validate(Array, true)
#5 C:\xampp\htdocs\ejb\app\ThirdParty\myth-auth\src\Controllers\AuthController.php(90): Myth\Auth\Authentication\LocalAuthenticator->attempt(Array, false)
#6 C:\xampp\htdocs\ejb\vendor\codeigniter4\framework\system\CodeIgniter.php(918): Myth\Auth\Controllers\AuthController->attemptLogin()
#7 C:\xampp\htdocs\ejb\vendor\codeigniter4\framework\system\CodeIgniter.php(404): CodeIgniter\CodeIgniter->runController(Object(Myth\Auth\Controllers\AuthController))
#8 C:\xampp\htdocs\ejb\vendor\codeigniter4\framework\system\CodeIgniter.php(312): CodeIgniter\CodeIgniter->handleRequest(NULL, Object(Config\Cache), false)
#9 C:\xampp\htdocs\ejb\public\index.php(45): CodeIgniter\CodeIgniter->run()
#10 C:\xampp\htdocs\ejb\vendor\codeigniter4\framework\system\Commands\Server\rewrite.php(34): require_once('C:\\xampp\\htdocs...')
#11 {main}
CRITICAL - 2021-05-02 22:06:22 --> Uncaught ErrorException: print_r(): Property access is not allowed yet in C:\xampp\htdocs\ejb\app\Views\errors\html\error_exception.php:100
Stack trace:
#0 [internal function]: CodeIgniter\Debug\Exceptions->errorHandler(2, 'print_r(): Prop...', 'C:\\xampp\\htdocs...', 100, Array)
#1 C:\xampp\htdocs\ejb\app\Views\errors\html\error_exception.php(100): print_r(Object(Myth\Auth\Controllers\AuthController), true)
#2 C:\xampp\htdocs\ejb\vendor\codeigniter4\framework\system\Debug\Exceptions.php(308): include('C:\\xampp\\htdocs...')
#3 C:\xampp\htdocs\ejb\vendor\codeigniter4\framework\system\Debug\Exceptions.php(174): CodeIgniter\Debug\Exceptions->render(Object(CodeIgniter\Database\Exceptions\DatabaseException), 500)
#4 [internal function]: CodeIgniter\Debug\Exceptions->exceptionHandler(Object(CodeIgniter\Database\Exceptions\DatabaseException))
#5 {main}
  thrown
#0 [internal function]: CodeIgniter\Debug\Exceptions->shutdownHandler()
#1 {main}
